Workbook

Sheet Raw_Data
A1: Customer_ID | B1: Revenue | C1: Cost_to_Serve | D1: Orders | E1: Return_Rate | F1: Return_Rate_Clean | G1: Support_Tickets | H1: Tenure_Months
A2: C001 | B2: 2658 | C2: 21973 | D2: 22 | E2: 0.22 | F2: =IF(E2>1, E2/100, E2) -> 0.22 | G2: 16 | H2: 23
A3: C002 | B3: 5103 | C3: 14484 | D3: 1 | E3: 15 | F3: =IF(E3>1, E3/100, E3) -> 0.15 | G3: 18 | H3: 14
A4: C003 | B4: 25079 | C4: 27280 | D4: 11 | E4: 0.18 | F4: =IF(E4>1, E4/100, E4) -> 0.18 | G4: 16 | H4: 56
A5: C004 | B5: 16960 | C5: 26875 | D5: 12 | E5: 0.21 | F5: =IF(E5>1, E5/100, E5) -> 0.21 | G5: 20 | H5: 10
A6: C005 | B6: 30841 | C6: 7986 | D6: 2 | E6: 0.12 | F6: =IF(E6>1, E6/100, E6) -> 0.12 | G6: 5 | H6: 9
A7: C006 | B7: 25139 | C7: 19876 | D7: 30 | E7: 12 | F7: =IF(E7>1, E7/100, E7) -> 0.12 | G7: 15 | H7: 53
A8: C007 | B8: 11116 | C8: 10808 | D8: 12 | E8: 0.25 | F8: =IF(E8>1, E8/100, E8) -> 0.25 | G8: 3 | H8: 11
A9: C008 | B9: 44869 | C9: 16868 | D9: 22 | E9: 0.24 | F9: =IF(E9>1, E9/100, E9) -> 0.24 | G9: 3 | H9: 38
A10: C009 | B10: 40105 | C10: 2256 | D10: 6 | E10: 0.25 | F10: =IF(E10>1, E10/100, E10) -> 0.25 | G10: 20 | H10: 57
A11: C010 | B11: 48507 | C11: 7943 | D11: 20 | E11: 0.17 | F11: =IF(E11>1, E11/100, E11) -> 0.17 | G11: 6 | H11: 39
A12: C011 | B12: 12530 | C12: 23509 | D12: 4 | E12: 0.3 | F12: =IF(E12>1, E12/100, E12) -> 0.3 | G12: 16 | H12: 58
A13: C012 | B13: 13702 | C13: 24076 | D13: 6 | E13: 6 | F13: =IF(E13>1, E13/100, E13) -> 0.06 | G13: 11 | H13: 2
... A30: C029 | B30: 33508 | C30: 7252 | D30: 27 | E30: 3 | F30: =IF(E30>1, E30/100, E30) -> 0.03 | G30: 14 | H30: 16
A31: C030 | B31: 31918 | D31: 9 | E31: 24 | F31: =IF(E31>1, E31/100, E31) -> 0.24 | G31: 20 | H31: 55
A32: C031 | B32: 21796 | C32: 24046 | D32: 20 | E32: 15 | F32: =IF(E32>1, E32/100, E32) -> 0.15 | G32: 18 | H32: 54
A33: C032 | B33: 49521 | C33: 19342 | D33: 5 | E33: 0.21 | F33: =IF(E33>1, E33/100, E33) -> 0.21 | G33: 8 | H33: 60
A34: C033 | B34: 24992 | C34: 6860 | D34: 25 | E34: 15 | F34: =IF(E34>1, E34/100, E34) -> 0.15 | G34: 15 | H34: 65
A35: C034 | B35: 14168 | C35: 2237 | D35: 6 | E35: 0.25 | F35: =IF(E35>1, E35/100, E35) -> 0.25 | G35: 3 | H35: 60
A36: C035 | B36: 13475 | C36: 3293 | D36: 9 | E36: 0.29 | F36: =IF(E36>1, E36/100, E36) -> 0.29 | G36: 17 | H36: 8
A37: C036 | B37: 29892 | C37: 28329 | D37: 14 | E37: 8 | F37: =IF(E37>1, E37/100, E37) -> 0.08 | G37: 2 | H37: 67
A38: C037 | B38: 10507 | C38: 28524 | D38: 20 | E38: 23 | F38: =IF(E38>1, E38/100, E38) -> 0.23 | G38: 3 | H38: 30
A39: C038 | B39: 44476 | C39: 8811 | D39: 8 | E39: 0.26 | F39: =IF(E39>1, E39/100, E39) -> 0.26 | G39: 10 | H39: 62
A40: C039 | B40: 17860 | C40: 23935 | D40: 26 | E40: 0.05 | F40: =IF(E40>1, E40/100, E40) -> 0.05 | G40: 16 | H40: 29
A41: C040 | B41: 16645 | C41: 29691 | D41: 8 | E41: 30 | F41: =IF(E41>1, E41/100, E41) -> 0.3 | G41: 13 | H41: 67
A42: C041 | B42: 8465 | C42: 27589 | D42: 6 | E42: 0.06 | F42: =IF(E42>1, E42/100, E42) -> 0.06 | G42: 1 | H42: 34
A43: C042 | B43: 43908 | C43: 24510 | D43: 25 | E43: 17 | F43: =IF(E43>1, E43/100, E43) -> 0.17 | G43: 19 | H43: 72
... A47: C046 | B47: 37702 | C47: 5541 | D47: 17 | E47: 8 | F47: =IF(E47>1, E47/100, E47) -> 0.08 | G47: 4 | H47: 52
A48: C047 | B48: 15213 | D48: 11 | E48: 0.05 | F48: =IF(E48>1, E48/100, E48) -> 0.05 | G48: 0 | H48: 69
A49: C048 | B49: 38465 | D49: 2 | E49: 25 | F49: =IF(E49>1, E49/100, E49) -> 0.25 | G49: 0 | H49: 12
A50: C049 | B50: 40964 | C50: 7316 | D50: 27 | E50: 0.3 | F50: =IF(E50>1, E50/100, E50) -> 0.3 | G50: 15 | H50: 45
A51: C050 | B51: 3354 | C51: 26453 | D51: 5 | E51: 10 | F51: =IF(E51>1, E51/100, E51) -> 0.1 | G51: 2 | H51: 55
A52: C051 | B52: 39754 | C52: 17071 | D52: 7 | E52: 0.19 | F52: =IF(E52>1, E52/100, E52) -> 0.19 | G52: 10 | H52: 65
A53: C052 | B53: 9655 | C53: 9733 | D53: 24 | E53: 0.13 | F53: =IF(E53>1, E53/100, E53) -> 0.13 | G53: 2 | H53: 46
A54: C053 | B54: 14600 | C54: 13535 | D54: 17 | E54: 13 | F54: =IF(E54>1, E54/100, E54) -> 0.13 | G54: 16 | H54: 14
A55: C054 | B55: 43298 | C55: 7241 | D55: 22 | E55: 3 | F55: =IF(E55>1, E55/100, E55) -> 0.03 | G55: 18 | H55: 30
A56: C055 | B56: 20624 | C56: 26135 | D56: 26 | E56: 0.18 | F56: =IF(E56>1, E56/100, E56) -> 0.18 | G56: 20 | H56: 42
A57: C056 | B57: 24598 | C57: 8860 | D57: 22 | E57: 19 | F57: =IF(E57>1, E57/100, E57) -> 0.19 | G57: 20 | H57: 35
A58: C057 | B58: 30928 | C58: 11129 | D58: 15 | E58: 30 | F58: =IF(E58>1, E58/100, E58) -> 0.3 | G58: 19 | H58: 56
A59: C058 | B59: 5161 | D59: 25 | E59: 28 | F59: =IF(E59>1, E59/100, E59) -> 0.28 | G59: 9 | H59: 48
...

Sheet Clean_Data
A1: Customer_ID | B1: Revenue | C1: Cost_to_Serve | D1: Orders | E1: Return_Rate | F1: Support_Tickets | G1: Tenure_Months | H1: Return_Rate_Clean | I1: Cost_Clean | J1: Median_Cost | K1: Revenue_Outlier
A2: =Raw_Data!A2 -> C001 | B2: 2658 | C2: 21973 | D2: 22 | E2: 0.22 | F2: 16 | G2: 23 | H2: =IF(ISNUMBER(SEARCH("%",E2)), VALUE(SUBSTITUTE(E2,"%",""))/100, E2) -> 0.22 | I2: =IF(C2="", $J$2, C2) -> 21973 | J2: =MEDIAN(C:C) -> 16549 | K2: =IF(B2>PERCENTILE($B:$B,0.95),"Yes","No") -> No
A3: =Raw_Data!A3 -> C002 | B3: 5103 | C3: 14484 | D3: 1 | E3: 15% | F3: 18 | G3: 14 | H3: =IF(ISNUMBER(SEARCH("%",E3)), VALUE(SUBSTITUTE(E3,"%",""))/100, E3) -> 0.15 | I3: =IF(C3="", $J$2, C3) -> 14484 | K3: =IF(B3>PERCENTILE($B:$B,0.95),"Yes","No") -> No
A4: =Raw_Data!A4 -> C003 | B4: 25079 | C4: 27280 | D4: 11 | E4: 0.18 | F4: 16 | G4: 56 | H4: =IF(ISNUMBER(SEARCH("%",E4)), VALUE(SUBSTITUTE(E4,"%",""))/100, E4) -> 0.18 | I4: =IF(C4="", $J$2, C4) -> 27280 | K4: =IF(B4>PERCENTILE($B:$B,0.95),"Yes","No") -> No
A5: =Raw_Data!A5 -> C004 | B5: 16960 | C5: 26875 | D5: 12 | E5: 0.21 | F5: 20 | G5: 10 | H5: =IF(ISNUMBER(SEARCH("%",E5)), VALUE(SUBSTITUTE(E5,"%",""))/100, E5) -> 0.21 | I5: =IF(C5="", $J$2, C5) -> 26875 | K5: =IF(B5>PERCENTILE($B:$B,0.95),"Yes","No") -> No
A6: =Raw_Data!A6 -> C005 | B6: 30841 | C6: 7986 | D6: 2 | E6: 0.12 | F6: 5 | G6: 9 | H6: =IF(ISNUMBER(SEARCH("%",E6)), VALUE(SUBSTITUTE(E6,"%",""))/100, E6) -> 0.12 | I6: =IF(C6="", $J$2, C6) -> 7986 | K6: =IF(B6>PERCENTILE($B:$B,0.95),"Yes","No") -> No
A7: =Raw_Data!A7 -> C006 | B7: 25139 | C7: 19876 | D7: 30 | E7: 12% | F7: 15 | G7: 53 | H7: =IF(ISNUMBER(SEARCH("%",E7)), VALUE(SUBSTITUTE(E7,"%",""))/100, E7) -> 0.12 | I7: =IF(C7="", $J$2, C7) -> 19876 | K7: =IF(B7>PERCENTILE($B:$B,0.95),"Yes","No") -> No
A8: =Raw_Data!A8 -> C007 | B8: 11116 | C8: 10808 | D8: 12 | E8: 0.25 | F8: 3 | G8: 11 | H8: =IF(ISNUMBER(SEARCH("%",E8)), VALUE(SUBSTITUTE(E8,"%",""))/100, E8) -> 0.25 | I8: =IF(C8="", $J$2, C8) -> 10808 | K8: =IF(B8>PERCENTILE($B:$B,0.95),"Yes","No") -> No
A9: =Raw_Data!A9 -> C008 | B9: 44869 | C9: 16868 | D9: 22 | E9: 0.24 | F9: 3 | G9: 38 | H9: =IF(ISNUMBER(SEARCH("%",E9)), VALUE(SUBSTITUTE(E9,"%",""))/100, E9) -> 0.24 | I9: =IF(C9="", $J$2, C9) -> 16868 | K9: =IF(B9>PERCENTILE($B:$B,0.95),"Yes","No") -> No
A10: =Raw_Data!A10 -> C009 | B10: 40105 | C10: 2256 | D10: 6 | E10: 0.25 | F10: 20 | G10: 57 | H10: =IF(ISNUMBER(SEARCH("%",E10)), VALUE(SUBSTITUTE(E10,"%",""))/100, E10) -> 0.25 | I10: =IF(C10="", $J$2, C10) -> 2256 | K10: =IF(B10>PERCENTILE($B:$B,0.95),"Yes","No") -> No
A11: =Raw_Data!A11 -> C010 | B11: 48507 | C11: 7943 | D11: 20 | E11: 0.17 | F11: 6 | G11: 39 | H11: =IF(ISNUMBER(SEARCH("%",E11)), VALUE(SUBSTITUTE(E11,"%",""))/100, E11) -> 0.17 | I11: =IF(C11="", $J$2, C11) -> 7943 | K11: =IF(B11>PERCENTILE($B:$B,0.95),"Yes","No") -> Yes
A12: =Raw_Data!A12 -> C011 | B12: 12530 | C12: 23509 | D12: 4 | E12: 0.3 | F12: 16 | G12: 58 | H12: =IF(ISNUMBER(SEARCH("%",E12)), VALUE(SUBSTITUTE(E12,"%",""))/100, E12) -> 0.3 | I12: =IF(C12="", $J$2, C12) -> 23509 | K12: =IF(B12>PERCENTILE($B:$B,0.95),"Yes","No") -> No
A13: =Raw_Data!A13 -> C012 | B13: 13702 | C13: 24076 | D13: 6 | E13: 6% | F13: 11 | G13: 2 | H13: =IF(ISNUMBER(SEARCH("%",E13)), VALUE(SUBSTITUTE(E13,"%",""))/100, E13) -> 0.06 | I13: =IF(C13="", $J$2, C13) -> 24076 | K13: =IF(B13>PERCENTILE($B:$B,0.95),"Yes","No") -> No
A14: =Raw_Data!A14 -> C013 | B14: 49946 | C14: 22297 | D14: 6 | E14: 21% | F14: 2 | G14: 72 | H14: =IF(ISNUMBER(SEARCH("%",E14)), VALUE(SUBSTITUTE(E14,"%",""))/100, E14) -> 0.21 | I14: =IF(C14="", $J$2, C14) -> 22297 | K14: =IF(B14>PERCENTILE($B:$B,0.95),"Yes","No") -> Yes
A15: =Raw_Data!A15 -> C014 | B15: 2841 | C15: 5160 | D15: 20 | E15: 0.14 | F15: 19 | G15: 50 | H15: =IF(ISNUMBER(SEARCH("%",E15)), VALUE(SUBSTITUTE(E15,"%",""))/100, E15) -> 0.14 | I15: =IF(C15="", $J$2, C15) -> 5160 | K15: =IF(B15>PERCENTILE($B:$B,0.95),"Yes","No") -> No
A16: =Raw_Data!A16 -> C015 | B16: 24430 | C16: 19343 | D16: 26 | E16: 19% | F16: 15 | G16: 19 | H16: =IF(ISNUMBER(SEARCH("%",E16)), VALUE(SUBSTITUTE(E16,"%",""))/100, E16) -> 0.19 | I16: =IF(C16="", $J$2, C16) -> 19343 | K16: =IF(B16>PERCENTILE($B:$B,0.95),"Yes","No") -> No
A17: =Raw_Data!A17 -> C016 | B17: 43130 | C17: 21994 | D17: 23 | E17: 0.13 | F17: 14 | G17: 44 | H17: =IF(ISNUMBER(SEARCH("%",E17)), VALUE(SUBSTITUTE(E17,"%",""))/100, E17) -> 0.13 | I17: =IF(C17="", $J$2, C17) -> 21994 | K17: =IF(B17>PERCENTILE($B:$B,0.95),"Yes","No") -> No
A18: =Raw_Data!A18 -> C017 | B18: 41312 | C18: 15974 | D18: 1 | E18: 0.13 | F18: 9 | G18: 30 | H18: =IF(ISNUMBER(SEARCH("%",E18)), VALUE(SUBSTITUTE(E18,"%",""))/100, E18) -> 0.13 | I18: =IF(C18="", $J$2, C18) -> 15974 | K18: =IF(B18>PERCENTILE($B:$B,0.95),"Yes","No") -> No
A19: =Raw_Data!A19 -> C018 | B19: 43466 | C19: 19122 | D19: 5 | E19: 13% | F19: 0 | G19: 11 | H19: =IF(ISNUMBER(SEARCH("%",E19)), VALUE(SUBSTITUTE(E19,"%",""))/100, E19) -> 0.13 | I19: =IF(C19="", $J$2, C19) -> 19122 | K19: =IF(B19>PERCENTILE($B:$B,0.95),"Yes","No") -> No
A20: =Raw_Data!A20 -> C019 | B20: 6420 | C20: 14730 | D20: 30 | E20: 0.02 | F20: 8 | G20: 57 | H20: =IF(ISNUMBER(SEARCH("%",E20)), VALUE(SUBSTITUTE(E20,"%",""))/100, E20) -> 0.02 | I20: =IF(C20="", $J$2, C20) -> 14730 | K20: =IF(B20>PERCENTILE($B:$B,0.95),"Yes","No") -> No
A21: =Raw_Data!A21 -> C020 | B21: 38243 | C21: 7779 | D21: 9 | E21: 6% | F21: 14 | G21: 1 | H21: =IF(ISNUMBER(SEARCH("%",E21)), VALUE(SUBSTITUTE(E21,"%",""))/100, E21) -> 0.06 | I21: =IF(C21="", $J$2, C21) -> 7779 | K21: =IF(B21>PERCENTILE($B:$B,0.95),"Yes","No") -> No
A22: =Raw_Data!A22 -> C021 | B22: 47981 | C22: 12177 | D22: 2 | E22: 0.25 | F22: 17 | G22: 69 | H22: =IF(ISNUMBER(SEARCH("%",E22)), VALUE(SUBSTITUTE(E22,"%",""))/100, E22) -> 0.25 | I22: =IF(C22="", $J$2, C22) -> 12177 | K22: =IF(B22>PERCENTILE($B:$B,0.95),"Yes","No") -> No
A23: =Raw_Data!A23 -> C022 | B23: 48072 | C23: 27827 | D23: 28 | E23: 30% | F23: 1 | G23: 6 | H23: =IF(ISNUMBER(SEARCH("%",E23)), VALUE(SUBSTITUTE(E23,"%",""))/100, E23) -> 0.3 | I23: =IF(C23="", $J$2, C23) -> 27827 | K23: =IF(B23>PERCENTILE($B:$B,0.95),"Yes","No") -> No
A24: =Raw_Data!A24 -> C023 | B24: 2729 | C24: 28066 | D24: 12 | E24: 0.18 | F24: 15 | G24: 71 | H24: =IF(ISNUMBER(SEARCH("%",E24)), VALUE(SUBSTITUTE(E24,"%",""))/100, E24) -> 0.18 | I24: =IF(C24="", $J$2, C24) -> 28066 | K24: =IF(B24>PERCENTILE($B:$B,0.95),"Yes","No") -> No
A25: =Raw_Data!A25 -> C024 | B25: 48456 | C25: 29990 | D25: 24 | E25: 0.19 | F25: 0 | G25: 27 | H25: =IF(ISNUMBER(SEARCH("%",E25)), VALUE(SUBSTITUTE(E25,"%",""))/100, E25) -> 0.19 | I25: =IF(C25="", $J$2, C25) -> 29990 | K25: =IF(B25>PERCENTILE($B:$B,0.95),"Yes","No") -> Yes
A26: =Raw_Data!A26 -> C025 | B26: 42662 | C26: 22929 | D26: 21 | E26: 0.19 | F26: 3 | G26: 14 | H26: =IF(ISNUMBER(SEARCH("%",E26)), VALUE(SUBSTITUTE(E26,"%",""))/100, E26) -> 0.19 | I26: =IF(C26="", $J$2, C26) -> 22929 | K26: =IF(B26>PERCENTILE($B:$B,0.95),"Yes","No") -> No
A27: =Raw_Data!A27 -> C026 | B27: 35379 | C27: 11518 | D27: 7 | E27: 7% | F27: 19 | G27: 38 | H27: =IF(ISNUMBER(SEARCH("%",E27)), VALUE(SUBSTITUTE(E27,"%",""))/100, E27) -> 0.07 | I27: =IF(C27="", $J$2, C27) -> 11518 | K27: =IF(B27>PERCENTILE($B:$B,0.95),"Yes","No") -> No
A28: =Raw_Data!A28 -> C027 | B28: 38190 | C28: 22035 | D28: 11 | E28: 0.07 | F28: 3 | G28: 10 | H28: =IF(ISNUMBER(SEARCH("%",E28)), VALUE(SUBSTITUTE(E28,"%",""))/100, E28) -> 0.07 | I28: =IF(C28="", $J$2, C28) -> 22035 | K28: =IF(B28>PERCENTILE($B:$B,0.95),"Yes","No") -> No
A29: =Raw_Data!A29 -> C028 | B29: 31980 | C29: 2145 | D29: 24 | E29: 0.17 | F29: 1 | G29: 48 | H29: =IF(ISNUMBER(SEARCH("%",E29)), VALUE(SUBSTITUTE(E29,"%",""))/100, E29) -> 0.17 | I29: =IF(C29="", $J$2, C29) -> 2145 | K29: =IF(B29>PERCENTILE($B:$B,0.95),"Yes","No") -> No
A30: =Raw_Data!A30 -> C029 | B30: 33508 | C30: 7252 | D30: 27 | E30: 3% | F30: 14 | G30: 16 | H30: =IF(ISNUMBER(SEARCH("%",E30)), VALUE(SUBSTITUTE(E30,"%",""))/100, E30) -> 0.03 | I30: =IF(C30="", $J$2, C30) -> 7252 | K30: =IF(B30>PERCENTILE($B:$B,0.95),"Yes","No") -> No
A31: =Raw_Data!A31 -> C030 | B31: 31918 | D31: 9 | E31: 24% | F31: 20 | G31: 55 | H31: =IF(ISNUMBER(SEARCH("%",E31)), VALUE(SUBSTITUTE(E31,"%",""))/100, E31) -> 0.24 | I31: =IF(C31="", $J$2, C31) -> 16549 | K31: =IF(B31>PERCENTILE($B:$B,0.95),"Yes","No") -> No
A32: =Raw_Data!A32 -> C031 | B32: 21796 | C32: 24046 | D32: 20 | E32: 15% | F32: 18 | G32: 54 | H32: =IF(ISNUMBER(SEARCH("%",E32)), VALUE(SUBSTITUTE(E32,"%",""))/100, E32) -> 0.15 | I32: =IF(C32="", $J$2, C32) -> 24046 | K32: =IF(B32>PERCENTILE($B:$B,0.95),"Yes","No") -> No
A33: =Raw_Data!A33 -> C032 | B33: 49521 | C33: 19342 | D33: 5 | E33: 0.21 | F33: 8 | G33: 60 | H33: =IF(ISNUMBER(SEARCH("%",E33)), VALUE(SUBSTITUTE(E33,"%",""))/100, E33) -> 0.21 | I33: =IF(C33="", $J$2, C33) -> 19342 | K33: =IF(B33>PERCENTILE($B:$B,0.95),"Yes","No") -> Yes
A34: =Raw_Data!A34 -> C033 | B34: 24992 | C34: 6860 | D34: 25 | E34: 15% | F34: 15 | G34: 65 | H34: =IF(ISNUMBER(SEARCH("%",E34)), VALUE(SUBSTITUTE(E34,"%",""))/100, E34) -> 0.15 | I34: =IF(C34="", $J$2, C34) -> 6860 | K34: =IF(B34>PERCENTILE($B:$B,0.95),"Yes","No") -> No
A35: =Raw_Data!A35 -> C034 | B35: 14168 | C35: 2237 | D35: 6 | E35: 0.25 | F35: 3 | G35: 60 | H35: =IF(ISNUMBER(SEARCH("%",E35)), VALUE(SUBSTITUTE(E35,"%",""))/100, E35) -> 0.25 | I35: =IF(C35="", $J$2, C35) -> 2237 | K35: =IF(B35>PERCENTILE($B:$B,0.95),"Yes","No") -> No
A36: =Raw_Data!A36 -> C035 | B36: 13475 | C36: 3293 | D36: 9 | E36: 0.29 | F36: 17 | G36: 8 | H36: =IF(ISNUMBER(SEARCH("%",E36)), VALUE(SUBSTITUTE(E36,"%",""))/100, E36) -> 0.29 | I36: =IF(C36="", $J$2, C36) -> 3293 | K36: =IF(B36>PERCENTILE($B:$B,0.95),"Yes","No") -> No
A37: =Raw_Data!A37 -> C036 | B37: 29892 | C37: 28329 | D37: 14 | E37: 8% | F37: 2 | G37: 67 | H37: =IF(ISNUMBER(SEARCH("%",E37)), VALUE(SUBSTITUTE(E37,"%",""))/100, E37) -> 0.08 | I37: =IF(C37="", $J$2, C37) -> 28329 | K37: =IF(B37>PERCENTILE($B:$B,0.95),"Yes","No") -> No
A38: =Raw_Data!A38 -> C037 | B38: 10507 | C38: 28524 | D38: 20 | E38: 23% | F38: 3 | G38: 30 | H38: =IF(ISNUMBER(SEARCH("%",E38)), VALUE(SUBSTITUTE(E38,"%",""))/100, E38) -> 0.23 | I38: =IF(C38="", $J$2, C38) -> 28524 | K38: =IF(B38>PERCENTILE($B:$B,0.95),"Yes","No") -> No
A39: =Raw_Data!A39 -> C038 | B39: 44476 | C39: 8811 | D39: 8 | E39: 0.26 | F39: 10 | G39: 62 | H39: =IF(ISNUMBER(SEARCH("%",E39)), VALUE(SUBSTITUTE(E39,"%",""))/100, E39) -> 0.26 | I39: =IF(C39="", $J$2, C39) -> 8811 | K39: =IF(B39>PERCENTILE($B:$B,0.95),"Yes","No") -> No
A40: =Raw_Data!A40 -> C039 | B40: 17860 | C40: 23935 | D40: 26 | E40: 0.05 | F40: 16 | G40: 29 | H40: =IF(ISNUMBER(SEARCH("%",E40)), VALUE(SUBSTITUTE(E40,"%",""))/100, E40) -> 0.05 | I40: =IF(C40="", $J$2, C40) -> 23935 | K40: =IF(B40>PERCENTILE($B:$B,0.95),"Yes","No") -> No
...

Sheet Calculations
A1: Note: Cost_to_Serve includes fixed, operational, and overhead costs; hence may exceed revenue for some customers.(in comparison to revenue to cost)
A2: Customer_ID | B2: Revenue | C2: Cost_Clean | D2: Return_Rate_Clean | E2: Customer_Profit | F2: Revenue_Threshold | G2: Profit_Threshold | H2: Customer_Segment | I2: High Rev – Low Profit | J2: High Rev – High Profit
A3: =Clean_Data!A2 -> C001 | B3: =Clean_Data!B2 -> 2658 | C3: =Clean_Data!I2 -> 21973 | D3: =Clean_Data!H2 -> 0.22 | E3: =B3-C3 -> -19315 | F3: =PERCENTILE(B:B,0.75) -> 39153 | G3: =PERCENTILE(E:E,0.75) -> 22865 | H3: =IF(AND(B3>=$F$3, E3>=$G$3), "High Rev – High Profit", IF(AND(B3>=$F$3, E3<$G$3), "High Rev – Low Profit", IF(AND(B3<$F$3, E3>=$G$3), "Low Rev – High Profit", "Low Rev – Low Profit"))) -> Low Rev – Low Profit | I3: =COUNTIF(H:H,"High Rev – Low Profit") -> 15 | J3: =COUNTIF(H:H,"High Rev – High Profit") -> 35
A4: =Clean_Data!A3 -> C002 | B4: =Clean_Data!B3 -> 5103 | C4: =Clean_Data!I3 -> 14484 | D4: =Clean_Data!H3 -> 0.15 | E4: =B4-C4 -> -9381 | H4: =IF(AND(B4>=$F$3, E4>=$G$3), "High Rev – High Profit", IF(AND(B4>=$F$3, E4<$G$3), "High Rev – Low Profit", IF(AND(B4<$F$3, E4>=$G$3), "Low Rev – High Profit", "Low Rev – Low Profit"))) -> Low Rev – Low Profit
A5: =Clean_Data!A4 -> C003 | B5: =Clean_Data!B4 -> 25079 | C5: =Clean_Data!I4 -> 27280 | D5: =Clean_Data!H4 -> 0.18 | E5: =B5-C5 -> -2201 | H5: =IF(AND(B5>=$F$3, E5>=$G$3), "High Rev – High Profit", IF(AND(B5>=$F$3, E5<$G$3), "High Rev – Low Profit", IF(AND(B5<$F$3, E5>=$G$3), "Low Rev – High Profit", "Low Rev – Low Profit"))) -> Low Rev – Low Profit
A6: =Clean_Data!A5 -> C004 | B6: =Clean_Data!B5 -> 16960 | C6: =Clean_Data!I5 -> 26875 | D6: =Clean_Data!H5 -> 0.21 | E6: =B6-C6 -> -9915 | H6: =IF(AND(B6>=$F$3, E6>=$G$3), "High Rev – High Profit", IF(AND(B6>=$F$3, E6<$G$3), "High Rev – Low Profit", IF(AND(B6<$F$3, E6>=$G$3), "Low Rev – High Profit", "Low Rev – Low Profit"))) -> Low Rev – Low Profit
A7: =Clean_Data!A6 -> C005 | B7: =Clean_Data!B6 -> 30841 | C7: =Clean_Data!I6 -> 7986 | D7: =Clean_Data!H6 -> 0.12 | E7: =B7-C7 -> 22855 | H7: =IF(AND(B7>=$F$3, E7>=$G$3), "High Rev – High Profit", IF(AND(B7>=$F$3, E7<$G$3), "High Rev – Low Profit", IF(AND(B7<$F$3, E7>=$G$3), "Low Rev – High Profit", "Low Rev – Low Profit"))) -> Low Rev – Low Profit
A8: =Clean_Data!A7 -> C006 | B8: =Clean_Data!B7 -> 25139 | C8: =Clean_Data!I7 -> 19876 | D8: =Clean_Data!H7 -> 0.12 | E8: =B8-C8 -> 5263 | H8: =IF(AND(B8>=$F$3, E8>=$G$3), "High Rev – High Profit", IF(AND(B8>=$F$3, E8<$G$3), "High Rev – Low Profit", IF(AND(B8<$F$3, E8>=$G$3), "Low Rev – High Profit", "Low Rev – Low Profit"))) -> Low Rev – Low Profit
A9: =Clean_Data!A8 -> C007 | B9: =Clean_Data!B8 -> 11116 | C9: =Clean_Data!I8 -> 10808 | D9: =Clean_Data!H8 -> 0.25 | E9: =B9-C9 -> 308 | H9: =IF(AND(B9>=$F$3, E9>=$G$3), "High Rev – High Profit", IF(AND(B9>=$F$3, E9<$G$3), "High Rev – Low Profit", IF(AND(B9<$F$3, E9>=$G$3), "Low Rev – High Profit", "Low Rev – Low Profit"))) -> Low Rev – Low Profit
A10: =Clean_Data!A9 -> C008 | B10: =Clean_Data!B9 -> 44869 | C10: =Clean_Data!I9 -> 16868 | D10: =Clean_Data!H9 -> 0.24 | E10: =B10-C10 -> 28001 | H10: =IF(AND(B10>=$F$3, E10>=$G$3), "High Rev – High Profit", IF(AND(B10>=$F$3, E10<$G$3), "High Rev – Low Profit", IF(AND(B10<$F$3, E10>=$G$3), "Low Rev – High Profit", "Low Rev – Low Profit"))) -> High Rev – High Profit
A11: =Clean_Data!A10 -> C009 | B11: =Clean_Data!B10 -> 40105 | C11: =Clean_Data!I10 -> 2256 | D11: =Clean_Data!H10 -> 0.25 | E11: =B11-C11 -> 37849 | H11: =IF(AND(B11>=$F$3, E11>=$G$3), "High Rev – High Profit", IF(AND(B11>=$F$3, E11<$G$3), "High Rev – Low Profit", IF(AND(B11<$F$3, E11>=$G$3), "Low Rev – High Profit", "Low Rev – Low Profit"))) -> High Rev – High Profit
A12: =Clean_Data!A11 -> C010 | B12: =Clean_Data!B11 -> 48507 | C12: =Clean_Data!I11 -> 7943 | D12: =Clean_Data!H11 -> 0.17 | E12: =B12-C12 -> 40564 | H12: =IF(AND(B12>=$F$3, E12>=$G$3), "High Rev – High Profit", IF(AND(B12>=$F$3, E12<$G$3), "High Rev – Low Profit", IF(AND(B12<$F$3, E12>=$G$3), "Low Rev – High Profit", "Low Rev – Low Profit"))) -> High Rev – High Profit
A13: =Clean_Data!A12 -> C011 | B13: =Clean_Data!B12 -> 12530 | C13: =Clean_Data!I12 -> 23509 | E13: =B13-C13 -> -10979 | H13: =IF(AND(B13>=$F$3, E13>=$G$3), "High Rev – High Profit", IF(AND(B13>=$F$3, E13<$G$3), "High Rev – Low Profit", IF(AND(B13<$F$3, E13>=$G$3), "Low Rev – High Profit", "Low Rev – Low Profit"))) -> Low Rev – Low Profit
A14: =Clean_Data!A13 -> C012 | B14: =Clean_Data!B13 -> 13702 | C14: =Clean_Data!I13 -> 24076 | D14: =Clean_Data!H13 -> 0.06 | E14: =B14-C14 -> -10374 | H14: =IF(AND(B14>=$F$3, E14>=$G$3), "High Rev – High Profit", IF(AND(B14>=$F$3, E14<$G$3), "High Rev – Low Profit", IF(AND(B14<$F$3, E14>=$G$3), "Low Rev – High Profit", "Low Rev – Low Profit"))) -> Low Rev – Low Profit
A15: =Clean_Data!A14 -> C013 | B15: =Clean_Data!B14 -> 49946 | C15: =Clean_Data!I14 -> 22297 | D15: =Clean_Data!H14 -> 0.21 | E15: =B15-C15 -> 27649 | H15: =IF(AND(B15>=$F$3, E15>=$G$3), "High Rev – High Profit", IF(AND(B15>=$F$3, E15<$G$3), "High Rev – Low Profit", IF(AND(B15<$F$3, E15>=$G$3), "Low Rev – High Profit", "Low Rev – Low Profit"))) -> High Rev – High Profit
A16: =Clean_Data!A15 -> C014 | B16: =Clean_Data!B15 -> 2841 | C16: =Clean_Data!I15 -> 5160 | D16: =Clean_Data!H15 -> 0.14 | E16: =B16-C16 -> -2319 | H16: =IF(AND(B16>=$F$3, E16>=$G$3), "High Rev – High Profit", IF(AND(B16>=$F$3, E16<$G$3), "High Rev – Low Profit", IF(AND(B16<$F$3, E16>=$G$3), "Low Rev – High Profit", "Low Rev – Low Profit"))) -> Low Rev – Low Profit
A17: =Clean_Data!A16 -> C015 | B17: =Clean_Data!B16 -> 24430 | C17: =Clean_Data!I16 -> 19343 | D17: =Clean_Data!H16 -> 0.19 | E17: =B17-C17 -> 5087 | H17: =IF(AND(B17>=$F$3, E17>=$G$3), "High Rev – High Profit", IF(AND(B17>=$F$3, E17<$G$3), "High Rev – Low Profit", IF(AND(B17<$F$3, E17>=$G$3), "Low Rev – High Profit", "Low Rev – Low Profit"))) -> Low Rev – Low Profit
A18: =Clean_Data!A17 -> C016 | B18: =Clean_Data!B17 -> 43130 | C18: =Clean_Data!I17 -> 21994 | D18: =Clean_Data!H17 -> 0.13 | E18: =B18-C18 -> 21136 | H18: =IF(AND(B18>=$F$3, E18>=$G$3), "High Rev – High Profit", IF(AND(B18>=$F$3, E18<$G$3), "High Rev – Low Profit", IF(AND(B18<$F$3, E18>=$G$3), "Low Rev – High Profit", "Low Rev – Low Profit"))) -> High Rev – Low Profit
A19: =Clean_Data!A18 -> C017 | B19: =Clean_Data!B18 -> 41312 | C19: =Clean_Data!I18 -> 15974 | D19: =Clean_Data!H18 -> 0.13 | E19: =B19-C19 -> 25338 | H19: =IF(AND(B19>=$F$3, E19>=$G$3), "High Rev – High Profit", IF(AND(B19>=$F$3, E19<$G$3), "High Rev – Low Profit", IF(AND(B19<$F$3, E19>=$G$3), "Low Rev – High Profit", "Low Rev – Low Profit"))) -> High Rev – High Profit
A20: =Clean_Data!A19 -> C018 | B20: =Clean_Data!B19 -> 43466 | C20: =Clean_Data!I19 -> 19122 | D20: =Clean_Data!H19 -> 0.13 | E20: =B20-C20 -> 24344 | H20: =IF(AND(B20>=$F$3, E20>=$G$3), "High Rev – High Profit", IF(AND(B20>=$F$3, E20<$G$3), "High Rev – Low Profit", IF(AND(B20<$F$3, E20>=$G$3), "Low Rev – High Profit", "Low Rev – Low Profit"))) -> High Rev – High Profit
A21: =Clean_Data!A20 -> C019 | B21: =Clean_Data!B20 -> 6420 | C21: =Clean_Data!I20 -> 14730 | D21: =Clean_Data!H20 -> 0.02 | E21: =B21-C21 -> -8310 | H21: =IF(AND(B21>=$F$3, E21>=$G$3), "High Rev – High Profit", IF(AND(B21>=$F$3, E21<$G$3), "High Rev – Low Profit", IF(AND(B21<$F$3, E21>=$G$3), "Low Rev – High Profit", "Low Rev – Low Profit"))) -> Low Rev – Low Profit
A22: =Clean_Data!A21 -> C020 | B22: =Clean_Data!B21 -> 38243 | C22: =Clean_Data!I21 -> 7779 | D22: =Clean_Data!H21 -> 0.06 | E22: =B22-C22 -> 30464 | H22: =IF(AND(B22>=$F$3, E22>=$G$3), "High Rev – High Profit", IF(AND(B22>=$F$3, E22<$G$3), "High Rev – Low Profit", IF(AND(B22<$F$3, E22>=$G$3), "Low Rev – High Profit", "Low Rev – Low Profit"))) -> Low Rev – High Profit
A23: =Clean_Data!A22 -> C021 | B23: =Clean_Data!B22 -> 47981 | C23: =Clean_Data!I22 -> 12177 | D23: =Clean_Data!H22 -> 0.25 | E23: =B23-C23 -> 35804 | H23: =IF(AND(B23>=$F$3, E23>=$G$3), "High Rev – High Profit", IF(AND(B23>=$F$3, E23<$G$3), "High Rev – Low Profit", IF(AND(B23<$F$3, E23>=$G$3), "Low Rev – High Profit", "Low Rev – Low Profit"))) -> High Rev – High Profit
A24: =Clean_Data!A23 -> C022 | B24: =Clean_Data!B23 -> 48072 | C24: =Clean_Data!I23 -> 27827 | D24: =Clean_Data!H23 -> 0.3 | E24: =B24-C24 -> 20245 | H24: =IF(AND(B24>=$F$3, E24>=$G$3), "High Rev – High Profit", IF(AND(B24>=$F$3, E24<$G$3), "High Rev – Low Profit", IF(AND(B24<$F$3, E24>=$G$3), "Low Rev – High Profit", "Low Rev – Low Profit"))) -> High Rev – Low Profit
A25: =Clean_Data!A24 -> C023 | B25: =Clean_Data!B24 -> 2729 | C25: =Clean_Data!I24 -> 28066 | D25: =Clean_Data!H24 -> 0.18 | E25: =B25-C25 -> -25337 | H25: =IF(AND(B25>=$F$3, E25>=$G$3), "High Rev – High Profit", IF(AND(B25>=$F$3, E25<$G$3), "High Rev – Low Profit", IF(AND(B25<$F$3, E25>=$G$3), "Low Rev – High Profit", "Low Rev – Low Profit"))) -> Low Rev – Low Profit
... A202: =Clean_Data!A201 -> C200 | B202: =Clean_Data!B201 -> 29872 | C202: =Clean_Data!I201 -> 16653 | D202: =Clean_Data!H201 -> 0.02 | E202: =B202-C202 -> 13219 | H202: =IF(AND(B202>=$F$3, E202>=$G$3), "High Rev – High Profit", IF(AND(B202>=$F$3, E202<$G$3), "High Rev – Low Profit", IF(AND(B202<$F$3, E202>=$G$3), "Low Rev – High Profit", "Low Rev – Low Profit"))) -> Low Rev – Low Profit

Sheet Pivot_Revenue
A3: Row Labels | B3: Sum of Revenue
A4: High Rev – High Profit | B4: 1583998
A5: High Rev – Low Profit | B5: 662715
A6: Low Rev – High Profit | B6: 540939
A7: Low Rev – Low Profit | B7: 2598679
A8: Grand Total | B8: 5386331

Sheet Segment_Profit
A3: Row Labels | B3: Sum of Customer_Profit
A4: High Rev – High Profit | B4: 1078734
A5: High Rev – Low Profit | B5: 281767
A6: Low Rev – High Profit | B6: 403934
A7: Low Rev – Low Profit | B7: 332115
A8: Grand Total | B8: 2096550

Sheet Segment_Margin
A3: Row Labels | B3: Sum of Revenue | C3: Sum of Customer_Profit | D3: Sum of Margin
A4: High Rev – High Profit | B4: 1583998 | C4: 1078734 | D4: 0.6810198
A5: High Rev – Low Profit | B5: 662715 | C5: 281767 | D5: 0.4251707
A6: Low Rev – High Profit | B6: 540939 | C6: 403934 | D6: 0.74672745
A7: Low Rev – Low Profit | B7: 2598679 | C7: 332115 | D7: 0.12780147
A8: Grand Total | B8: 5386331 | C8: 2096550 | D8: 0.38923527

Sheet Segment_Actions
A1: Segment | B1: Key Insight | C1: Business Action
A2: High Rev – High Profit | B2: Core profit driver | C2: Retain, loyalty, premium support
A3: High Rev – Low Profit | B3: Revenue strong, margin weak | C3: Cost optimization, pricing review
A4: Low Rev – High Profit | B4: Highest efficiency | C4: Upsell, scale acquisition
A5: Low Rev – Low Profit | B5: High volume, low return | C5: Automate, prune, or reprice

Sheet Chart_Data
A1: Segment | B1: Revenue | C1: Margin | D1: Profit
A2: High Rev – High Profit | B2: 1583998 | C2: 0.681 | D2: 1078734
A3: High Rev – Low Profit | B3: 662715 | C3: 0.4252 | D3: 281767
A4: Low Rev – High Profit | B4: 540939 | C4: 0.7467 | D4: 403934
A5: Low Rev – Low Profit | B5: 2598679 | C5: 0.1278 | D5: 332115

Sheet Insights
A1: Segment 1: High Revenue – High Profit
A2: Insight: | B2: This segment contributes the highest share of total profit while also driving top-line revenue
A3: Business Meaning: | B3: These customers are the most efficient and valuable; pricing, costs, and return behavior are all working in the company’s favor.
A4: Action: | B4: Retain aggressively, avoid heavy discounting, and use this segment as the benchmark for defining the ideal customer profile.
A6: Segment 2: High Revenue – Low Profit
A7: Insight: | B7: Despite strong revenue, profitability is weak due to high costs, returns, or discounts.
A8: Business Meaning: | B8: Revenue alone is misleading here — this segment puts pressure on margins and operational efficiency.
A9: Action: | B9: Investigate cost drivers, tighten discount policies, reduce returns, or renegotiate pricing to restore profitability.
A11: Segment 3: Low Revenue – High Profit
A12: Insight: | B12: This segment delivers strong margins but contributes limited overall revenue.
A13: Business Meaning: | B13: These customers are efficient but under-scaled, indicating missed growth potential.
A14: Action: | B14: Target selectively for upselling and cross-selling to increase revenue without sacrificing margins.
A16: Segment 4: Low Revenue – Low Profit
A17: Insight: | B17: This segment generates minimal revenue and weak profitability, offering the least business value.
A18: Business Meaning: | B18: These customers consume resources without meaningful financial return.
A19: Action: | B19: Reduce service intensity, apply stricter pricing, or consider deprioritizing this segment altogether.

Sheet Dashboard
A1: Customer Revenue–Profit Segmentation Dashboard
B3: Updated:
B4: =TODAY() -> 46018
B5: Total Revenue | D5: Total Profit | F5: Avg Profit Margin | H5: Highest Profit Segment
B6: =SUM(Calculations!B:B) -> 5386331 | D6: =SUM(Calculations!E:E) -> 2096550 | F6: =AVERAGE(Calculations!F:F) -> 39153 | H6: High Revenue – High Profit
